Workbook

Sheet START HERE
A1: LIGHTSHOW PLATFORM — FINANCIAL MODEL
A2: START HERE — what this model does and what to do with it
B4: WHAT IS THIS?
B5: This spreadsheet models the financial reality of your Christmas light show platform. It answers: how much will this cost to run, how much will it make, and how many paying users do you need before you stop burning cash. There are 6 sheets below. You only need to touch ONE of them.
B7: THE 6 SHEETS — WHAT EACH ONE IS FOR
B8: ASSUMPTIONS | C8: The only sheet you need to edit. Change the yellow cells to adjust user counts, pricing, AI credit costs, storage, marketplace settings, and more. Every other sheet recalculates automatically when you change something here.
B9: REVENUE | C9: Shows exactly where every dollar comes from: subscriptions, AI credit top-up sales, storage overages, marketplace take, and product sales. Broken down by user tier.
B10: COSTS | C10: Every cost you'll have: Vercel, Supabase, Clerk, Cloudflare, Resend, Sentry, Stripe, AI compute, storage. Fixed costs plus variable costs per tier.
B11: P&L SUMMARY | C11: The bottom line. Revenue minus costs = how much you're making or burning per month. Also shows Year 1/2/3 projections and a launch reality check section.
B12: SCENARIOS | C12: Dial multipliers from 0-2x to see Base / Conservative / Worst / Best case side by side. Change one number, all four scenarios update instantly.
B13: PRODUCTS | C13: Revenue from non-subscription products: yard signs, effect packs, sequence packs, consultations, affiliate hardware. Adjust the blue 'units/mo' column to estimate.
B15: YOUR CURRENT NUMBERS AT A GLANCE (based on ASSUMPTIONS inputs)
B16: Starting users (Month 1) | C16: =ASSUMPTIONS!B5&" Free | "&ASSUMPTIONS!B6&" Creator | "&ASSUMPTIONS!B7&" Pro | "&ASSUMPTIONS!B8&" Installer" -> 100 Free | 15 Creator | 8 Pro | 2 Installer
B17: Monthly gross revenue | C17: =REVENUE!F29 -> 1054.04 | D17: All revenue streams — subscriptions, top-ups, marketplace, products
B18: Monthly costs | C18: =COSTS!F36 -> 151.98 | D18: Fixed platform + AI compute + storage + marketplace overhead
B19: Net monthly result | C19: =REVENUE!F31-COSTS!F36 -> 863.99 | D19: Positive = profit. Negative = how much cash you burn each month.
B20: Gross margin % | C20: =IF(REVENUE!F31>0,(REVENUE!F31-COSTS!F36)/REVENUE!F31,0) -> 0.85040897 | D20: Revenue kept after all direct costs. SaaS target is 70%+.
B22: WHAT TO FOCUS ON FIRST
B23: Step 1: Go to ASSUMPTIONS | C23: Change the yellow 'USER COUNTS' cells to reflect where you realistically think you'll be at launch. Be honest — most founders overestimate early traction. The default (15 Creator, 8 Pro, 2 Installer) is already conservative.
B24: Step 2: Check P&L SUMMARY | C24: Look at 'Net Monthly Result.' That number is your monthly burn rate at launch. It'll be negative. That's normal and expected. The question is: how negative, and how long can you sustain it before you hit break-even?
B25: Step 3: Run SCENARIOS | C25: Set the Conservative multipliers to something painful — like 0.3x users. If you still don't go bankrupt in that scenario, you have a resilient model. If you do, you need a lower cost base or a faster path to paying users.
B26: Step 4: Adjust ASSUMPTIONS to stress-test | C26: The most important assumptions to stress-test: Creator/Pro user counts, monthly churn rate (Creator 7% is high — what if it's 12%?), and the AI credit cost per 1,000. These three drive 90% of your outcome.
B27: Step 5: Come back in October | C27: This is a seasonal business. The model assumes flat monthly users, but reality is: almost zero activity June-September, then an explosion in November-December. Plan cash accordingly.
B29: FIVE NUMBERS THAT MATTER
B30: $132/mo | C30: Your fixed platform costs at launch | D30: Vercel, Supabase, Sentry, Resend, GitHub, domain, misc. This is your floor — you spend this whether you have 1 user or 1,000. Know it cold.
B31: ~$0.92/user/mo | C31: Your true cost to serve a Pro user | D31: Storage ($0.12) + AI credits ($0.60) + compute ($0.20) = $0.92. On a $49 plan, that's a 98%+ gross margin. AI credits are the only variable that matters.
B32: $0.10 / 1,000 credits | C32: What AI actually costs you | D32: Blended Haiku + Sonnet rate. One full sequence generation = ~100 credits = $0.01. A Pro user maxing 6,000 credits/mo = $0.60 in AI cost. Entirely manageable.
B33: 50 credits — lifetime | C33: What Free users get, ever | D33: Not per month. Not per year. 50 total. Enough to try it 3-4 times. After that: upgrade or you're done with AI. This is your primary conversion lever.
B34: 2.9% + $0.30 | C34: What Stripe takes from every single transaction | D34: On a $19/mo Creator sub, Stripe keeps $0.85. On a $9 top-up, Stripe keeps $0.56. Small but real — at 1,000 transactions it adds up fast.
B36: All formulas in this model are live. Change ASSUMPTIONS → everything updates. Yellow cells = your inputs. Blue inputs in SCENARIOS = multipliers. Do not edit black or green cells — those are calculated.

Sheet ASSUMPTIONS
A1: LIGHTSHOW PLATFORM — FINANCIAL MODEL ASSUMPTIONS
A2: Blue cells = your inputs (change these). All other sheets recalculate automatically. Defaults are deliberately conservative. Adjust to stress-test.
A3: ASSUMPTION | B3: VALUE | C3: NOTES / CONTEXT | E3: ASSUMPTION | F3: VALUE | G3: NOTES / CONTEXT
A4: USER COUNTS — Starting Month 1 | E4: PLATFORM FIXED COSTS (Monthly)
A5: Free Users (50 lifetime AI credits — ever) | B5: 100 | C5: Curious/trial. Zero recurring revenue. Costs ~$0.04/mo each in storage + AI. | E5: Vercel Pro (hosting + CDN + serverless) | F5: 20 | G5: Pro $20/mo. Scales to ~$50-100 at 1K+ MAU with heavy serverless usage.
A6: Creator Users ($19/mo) | B6: 15 | C6: Single-home Christmas show. Bread-and-butter tier. | E6: Supabase Pro (DB + realtime + storage meta) | F6: 25 | G6: Includes 8GB DB, 100GB storage, 2M realtime messages.
A7: Pro Users ($49/mo) | B7: 8 | C7: The obsessed hobbyist. 8K pixels, 4 controllers. | E7: Clerk Auth — cost per MAU over 10K free | F7: 0.02 | G7: Free up to 10K MAU. Use (total users × this rate) if over 10K.
A8: Installer Users ($149/mo) | B8: 2 | C8: Commercial operators. Multiple client shows per season. | E8: Cloudflare R2 base fee | F8: 0 | G8: Free: 10GB, 1M Class A ops, 10M Class B ops. Then $0.015/GB. Zero egress.
E9: Resend (transactional email) | F9: 20 | G9: Billing receipts, credit alerts, export notifications.
A10: PRICING | E10: Sentry (error + performance monitoring) | F10: 26 | G10: Team plan. 50K errors/mo. Worth every penny.
A11: Creator Monthly Price | B11: 19 | E11: GitHub (code + CI/CD actions) | F11: 4 | G11: Team plan with Actions minutes.
A12: Pro Monthly Price | B12: 49 | E12: Domain + DNS + SSL | F12: 2 | G12: ~$24/yr domain amortized. Cloudflare DNS free. SSL auto-managed.
A13: Installer Monthly Price | B13: 149 | E13: Stripe Processing Fee % | F13: 0.029 | G13: Standard 2.9% + $0.30 applied to ALL revenue transactions.
A14: Annual Plan Discount % | B14: 0.15 | C14: 15% off. No free months — chargeback risk on seasonal product. | E14: Stripe Fixed Fee per Transaction ($) | F14: 0.3 | G14: The $0.30 flat charge per charge event. Hurts most on small top-up packs.
A15: % Creator Users on Annual Plan | B15: 0.12 | C15: Conservative. Seasonality makes annual commitment harder to sell. | E15: Anthropic API Monthly Budget Buffer | F15: 10 | G15: Monthly AI API safety buffer for unexpected usage spikes.
A16: % Pro Users on Annual Plan | B16: 0.2 | C16: More committed hobbyists. Higher annual adoption. | E16: Miscellaneous / Unplanned | F16: 25 | G16: There's ALWAYS something. New tool, one-off service, surprise fee. Keep this line.
A17: % Installer Users on Annual Plan | B17: 0.35 | C17: Business users plan ahead.
A19: AI CREDITS — Model: Haiku for simple / Sonnet for generation | E19: MARKETPLACE
A20: AI Cost per 1,000 Credits ($) | B20: 0.1 | C20: Blended Haiku+Sonnet. ~$0.08-0.14 per full generation @ 100 credits. | E20: Avg Marketplace Transaction Value ($) | F20: 15 | G20: Sequence packs, effects, presets, show designs.
A21: Free Tier Credits (lifetime total, NOT monthly) | B21: 50 | C21: 50 ever. Once gone: upgrade or no more AI. Creates conversion urgency. | E21: Avg Transactions per Active Seller / Mo | F21: 3 | G21: Conservative. Mostly Nov-Jan, near-zero off-season.
A22: Creator Credits / Month | B22: 1500 | C22: ~15 full generations. Enough for one solid home show. | E22: % Creator Users Who Sell | F22: 0.08 | G22: ~1 in 12.
A23: Pro Credits / Month | B23: 6000 | C23: ~60 generations. Rolls over up to 2x cap. | E23: % Pro Users Who Sell | F23: 0.2 | G23: ~1 in 5. Ambitious hobbyists are more likely to monetize their work.
A24: Installer Credits / Month | B24: 25000 | C24: ~250 generations. Covers AI Batch on 10-15 client shows. | E24: % Installer Users Who Sell | F24: 0.15 | G24: Some list their sequences; most are focused on client installs.
A25: Top-Up Pack A (1,000 credits) — Sell Price | B25: 9 | E25: Platform Take — Free Sellers | F25: 0.5 | G25: Platform keeps 50%, seller keeps 50%.
A26: Top-Up Pack A (1,000 credits) — Your Cost | B26: 0.1 | C26: Anthropic compute cost to deliver 1,000 credits to the user. | E26: Platform Take — Creator Sellers | F26: 0.4 | G26: Platform 40%, seller 60%.
A27: Top-Up Pack B (5,000 credits) — Sell Price | B27: 39 | E27: Platform Take — Pro Sellers | F27: 0.3 | G27: Platform 30%, seller 70%.
A28: Top-Up Pack B (5,000 credits) — Your Cost | B28: 0.5 | E28: Platform Take — Installer Sellers | F28: 0.25 | G28: Platform 25%, seller 75%.
A29: % Creator Buying Top-Ups / Mo | B29: 0.05 | C29: 1 in 20 Creator users buys a top-up each month. Nov spike likely. | E29: Marketplace Stripe Processing % | F29: 0.029 | G29: Stripe charges a fee on every marketplace payout too.
A30: % Pro Buying Top-Ups / Mo | B30: 0.15 | C30: 1 in 7.
A31: % Installer Buying Top-Ups / Mo | B31: 0.25 | C31: 1 in 4. Heavy AI Batch users.
A32: Avg Top-Up Purchase Value ($) | B32: 22 | C32: Blended average: Pack A ($9) and Pack B ($39). | E32: PHYSICAL & DIGITAL PRODUCTS
A33: Avg Top-Up Compute Cost to Deliver ($) | B33: 0.3 | C33: Your blended AI compute cost to fulfill avg top-up purchase. | E33: Yard Sign — Digital Printable PDF Price | F33: 12 | G33: "Tune to 88.9 FM" custom sign. Instant delivery. Near-100% margin.
E34: Yard Sign — Physical (Printed + Shipped) Price | F34: 35 | G34: Weatherproof corrugated. Print-on-demand via Printful/Gelato.
A35: STORAGE — Cloudflare R2 (no egress fees) | E35: Effect Pack Price | F35: 15 | G35: Premium effects not in base subscription.
A36: Storage Cost per GB / Month ($) | B36: 0.015 | C36: R2 pricing. ZERO egress charges. S3 would cost 10-50x more on bandwidth for a media-heavy app. | E36: Sequence Pack Price | F36: 20 | G36: Ready-to-use sequences for popular holiday songs.
A37: Avg Storage — Free User (GB) | B37: 0.2 | C37: One project, minimal history. ~200 MB. | E37: Show Planning Consultation Price | F37: 99 | G37: 1-hr video call. High-touch upsell for new Installers.
A38: Avg Storage — Creator User (GB) | B38: 1.5 | C38: 3-5 projects + 90-day version history. | E38: % Paying Users Purchasing Product / Mo | F38: 0.02 | G38: 1 in 50 paying users per month. Very seasonal — most purchases Oct-Dec.
A39: Avg Storage — Pro User (GB) | B39: 8 | C39: 10-20 shows + 1-year version history. | E39: COGS — Digital Sign ($) | F39: 0.5 | G39: Storage + PDF generation. Near-zero cost.
A40: Avg Storage — Installer User (GB) | B40: 50 | C40: 50+ client shows. Cold-archive after 90 days idle saves ~70% of hot storage cost. | E40: COGS — Physical Sign ($) | F40: 14 | G40: Print + ship via print-on-demand. Varies by region.
A41: Storage Overage Add-On Price / Mo ($) | B41: 5 | C41: Per 50GB over quota. Soft cap — email warning at 110%, block new shows at 130%. | E41: COGS — Effect Pack ($) | F41: 0 | G41: Pure digital. Zero COGS.
...

Sheet REVENUE
A1: REVENUE MODEL — MONTHLY SNAPSHOT
A2: All values pull from ASSUMPTIONS sheet. Change inputs there. This sheet shows one-month revenue at current user counts.
A3: REVENUE LINE | B3: FREE | C3: CREATOR | D3: PRO | E3: INSTALLER | F3: TOTAL / MO | G3: NOTES
A4: SUBSCRIPTION REVENUE (MRR)
A5: Monthly-pay subscribers | B5: =0 -> 0 | C5: =ROUND(ASSUMPTIONS!B6*(1-ASSUMPTIONS!B15),0) -> 13 | D5: =ROUND(ASSUMPTIONS!B7*(1-ASSUMPTIONS!B16),0) -> 6 | E5: =ROUND(ASSUMPTIONS!B8*(1-ASSUMPTIONS!B17),0) -> 1 | G5: Users on monthly billing
A6: Annual-plan subscribers (amortized/mo) | B6: =0 -> 0 | C6: =ROUND(ASSUMPTIONS!B6*ASSUMPTIONS!B15,0) -> 2 | D6: =ROUND(ASSUMPTIONS!B7*ASSUMPTIONS!B16,0) -> 2 | E6: =ROUND(ASSUMPTIONS!B8*ASSUMPTIONS!B17,0) -> 1 | G6: Annual users — billed upfront, amortized here
A7: Revenue from monthly subscribers | B7: 0 | C7: =ROUND(ASSUMPTIONS!B6*(1-ASSUMPTIONS!B15)*ASSUMPTIONS!B11,2) -> 250.8 | D7: =ROUND(ASSUMPTIONS!B7*(1-ASSUMPTIONS!B16)*ASSUMPTIONS!B12,2) -> 313.6 | E7: =ROUND(ASSUMPTIONS!B8*(1-ASSUMPTIONS!B17)*ASSUMPTIONS!B13,2) -> 193.7
A8: Revenue from annual subscribers (amortized/mo) | B8: =0 -> 0 | C8: =ROUND(ASSUMPTIONS!B6*ASSUMPTIONS!B15*ASSUMPTIONS!B11*(1-ASSUMPTIONS!B14),2) -> 29.07 | D8: =ROUND(ASSUMPTIONS!B7*ASSUMPTIONS!B16*ASSUMPTIONS!B12*(1-ASSUMPTIONS!B14),2) -> 66.64 | E8: =ROUND(ASSUMPTIONS!B8*ASSUMPTIONS!B17*ASSUMPTIONS!B13*(1-ASSUMPTIONS!B14),2) -> 88.66
A9: TOTAL SUBSCRIPTION REVENUE | B9: =0 -> 0 | C9: =ROUND(ASSUMPTIONS!B6*(1-ASSUMPTIONS!B15)*ASSUMPTIONS!B11+ASSUMPTIONS!B6*ASSUMPTIONS!B15*ASSUMPTIONS!B11*(1-ASSUMPTIONS!B14),2) -> 279.87 | D9: =ROUND(ASSUMPTIONS!B7*(1-ASSUMPTIONS!B16)*ASSUMPTIONS!B12+ASSUMPTIONS!B7*ASSUMPTIONS!B16*ASSUMPTIONS!B12*(1-ASSUMPTIONS!B14),2) -> 380.24 | E9: =ROUND(ASSUMPTIONS!B8*(1-ASSUMPTIONS!B17)*ASSUMPTIONS!B13+ASSUMPTIONS!B8*ASSUMPTIONS!B17*ASSUMPTIONS!B13*(1-ASSUMPTIONS!B14),2) -> 282.36 | F9: =SUM(B9:E9) -> 942.47 | G9: Your monthly recurring subscription base
A11: AI CREDIT TOP-UP SALES (Add-On Revenue)
A12: Creator users buying top-ups | B12: =0 -> 0 | C12: =ROUND(ASSUMPTIONS!B6*ASSUMPTIONS!B29,1) -> 0.8 | D12: =0 -> 0 | E12: =0 -> 0
A13: Pro users buying top-ups | B13: =0 -> 0 | C13: =0 -> 0 | D13: =ROUND(ASSUMPTIONS!B7*ASSUMPTIONS!B30,1) -> 1.2 | E13: =0 -> 0
A14: Installer users buying top-ups | B14: =0 -> 0 | C14: =0 -> 0 | D14: =0 -> 0 | E14: =ROUND(ASSUMPTIONS!B8*ASSUMPTIONS!B31,1) -> 0.5
A15: TOTAL TOP-UP REVENUE | B15: =0 -> 0 | C15: =ROUND(ASSUMPTIONS!B6*ASSUMPTIONS!B29*ASSUMPTIONS!B32,2) -> 16.5 | D15: =ROUND(ASSUMPTIONS!B7*ASSUMPTIONS!B30*ASSUMPTIONS!B32,2) -> 26.4 | E15: =ROUND(ASSUMPTIONS!B8*ASSUMPTIONS!B31*ASSUMPTIONS!B32,2) -> 11 | F15: =SUM(B15:E15) -> 53.9 | G15: Top-ups are high-margin: ~$22 revenue / ~$0.30 cost each
A17: STORAGE OVERAGE ADD-ONS
A18: TOTAL STORAGE OVERAGE REVENUE | B18: =0 -> 0 | C18: =ROUND(ASSUMPTIONS!B6*ASSUMPTIONS!B42*ASSUMPTIONS!B41,2) -> 1.5 | D18: =ROUND(ASSUMPTIONS!B7*ASSUMPTIONS!B43*ASSUMPTIONS!B41,2) -> 2 | E18: =ROUND(ASSUMPTIONS!B8*ASSUMPTIONS!B44*ASSUMPTIONS!B41,2) -> 1 | F18: =SUM(B18:E18) -> 4.5 | G18: $5/50GB add-on. Small but real.
A20: MARKETPLACE — PLATFORM'S SHARE OF GMV
A21: Gross Merchandise Value (GMV) — all sellers | B21: 0 | C21: =ROUND(ASSUMPTIONS!B6*ASSUMPTIONS!F22*ASSUMPTIONS!F21*ASSUMPTIONS!F20,2) -> 54 | D21: =ROUND(ASSUMPTIONS!B7*ASSUMPTIONS!F23*ASSUMPTIONS!F21*ASSUMPTIONS!F20,2) -> 72 | E21: =ROUND(ASSUMPTIONS!B8*ASSUMPTIONS!F24*ASSUMPTIONS!F21*ASSUMPTIONS!F20,2) -> 13.5 | F21: =SUM(B21:E21) -> 139.5 | G21: Total sales volume flowing through marketplace
A22: PLATFORM'S MARKETPLACE REVENUE (net of Stripe) | B22: 0 | C22: =ROUND(C21*ASSUMPTIONS!F26*(1-ASSUMPTIONS!F29),2) -> 20.97 | D22: =ROUND(D21*ASSUMPTIONS!F27*(1-ASSUMPTIONS!F29),2) -> 20.97 | E22: =ROUND(E21*ASSUMPTIONS!F28*(1-ASSUMPTIONS!F29),2) -> 3.28 | F22: =SUM(B22:E22) -> 45.22 | G22: Your take from marketplace GMV after Stripe
A24: PHYSICAL & DIGITAL PRODUCT REVENUE
A25: TOTAL PRODUCT REVENUE (gross) | B25: =0 -> 0 | C25: =0 -> 0 | D25: =0 -> 0 | E25: =0 -> 0 | F25: =ROUND((ASSUMPTIONS!B6+ASSUMPTIONS!B7+ASSUMPTIONS!B8)*ASSUMPTIONS!F38*((ASSUMPTIONS!F33*0.4)+(ASSUMPTIONS!F34*0.3)+(ASSUMPTIONS!F35*0.2)+(ASSUMPTIONS!F36*0.1)),2) -> 10.15 | G25: 40% digital signs, 30% physical signs, 20% effect packs, 10% sequence packs (assumed mix)
A26: Less: Product COGS (print/ship/delivery) | F26: =ROUND((ASSUMPTIONS!B6+ASSUMPTIONS!B7+ASSUMPTIONS!B8)*ASSUMPTIONS!F38*((ASSUMPTIONS!F39*0.4)+(ASSUMPTIONS!F40*0.3)+(ASSUMPTIONS!F41*0.2)+(ASSUMPTIONS!F42*0.1)),2) -> 2.2 | G26: Physical sign COGS is real (~$14). Digital is near-zero.
A27: NET PRODUCT REVENUE (after COGS) | F27: =F25-F26 -> 7.95
A29: TOTAL GROSS REVENUE / MONTH | F29: =ROUND(F9+F15+F18+F22+F27,2) -> 1054.04 | G29: All revenue streams combined
A30: Less: Stripe Processing (2.9% + $0.30/txn est) | F30: =ROUND(F29*ASSUMPTIONS!F13+(ASSUMPTIONS!B6+ASSUMPTIONS!B7+ASSUMPTIONS!B8)*ASSUMPTIONS!F14,2) -> 38.07 | G30: Stripe takes this off the top of every charge
A31: NET REVENUE / MONTH (after Stripe) | F31: =F29-F30 -> 1015.97

Sheet COSTS
A1: INFRASTRUCTURE & OPERATING COSTS — MONTHLY
A2: Conservative estimates throughout. Granular by cost type and tier. All pull from ASSUMPTIONS.
A3: COST LINE | B3: FREE | C3: CREATOR | D3: PRO | E3: INSTALLER | F3: TOTAL / MO | G3: NOTES
A4: FIXED PLATFORM COSTS (same regardless of users)
A5: Vercel Pro (hosting + CDN + serverless functions) | B5: =0 -> 0 | C5: =0 -> 0 | D5: =0 -> 0 | E5: =0 -> 0 | F5: =ASSUMPTIONS!F5 -> 20 | G5: Flat $20/mo. Increases to ~$50+ at scale with function invocations.
A6: Supabase Pro (DB + realtime + storage metadata) | B6: =0 -> 0 | C6: =0 -> 0 | D6: =0 -> 0 | E6: =0 -> 0 | F6: =ASSUMPTIONS!F6 -> 25 | G6: Covers DB, realtime subscriptions, 50K MAU auth.
A7: Cloudflare R2 (base tier, zero egress) | B7: =0 -> 0 | C7: =0 -> 0 | D7: =0 -> 0 | E7: =0 -> 0 | F7: =ASSUMPTIONS!F8 -> 0 | G7: Free under 10GB/1M ops. R2 has NO egress fees — critical cost saver.
A8: Resend (transactional email) | B8: =0 -> 0 | C8: =0 -> 0 | D8: =0 -> 0 | E8: =0 -> 0 | F8: =ASSUMPTIONS!F9 -> 20 | G8: Billing receipts, credit-low alerts, export ready notifications.
A9: Sentry (error + performance monitoring) | B9: =0 -> 0 | C9: =0 -> 0 | D9: =0 -> 0 | E9: =0 -> 0 | F9: =ASSUMPTIONS!F10 -> 26 | G9: Team plan. Error tracking + performance. Non-negotiable for reliability.
A10: GitHub (code hosting + CI/CD actions) | B10: =0 -> 0 | C10: =0 -> 0 | D10: =0 -> 0 | E10: =0 -> 0 | F10: =ASSUMPTIONS!F11 -> 4 | G10: Team plan covers all Actions minutes for normal deployment.
A11: Domain + DNS + SSL certificates | B11: =0 -> 0 | C11: =0 -> 0 | D11: =0 -> 0 | E11: =0 -> 0 | F11: =ASSUMPTIONS!F12 -> 2 | G11: ~$24/yr domain amortized. Cloudflare DNS free. SSL auto-managed.
A12: Anthropic API monthly budget buffer | B12: =0 -> 0 | C12: =0 -> 0 | D12: =0 -> 0 | E12: =0 -> 0 | F12: =ASSUMPTIONS!F15 -> 10 | G12: Safety net for unexpected AI usage spikes. Adjust as usage scales.
A13: Miscellaneous / unplanned costs | B13: =0 -> 0 | C13: =0 -> 0 | D13: =0 -> 0 | E13: =0 -> 0 | F13: =ASSUMPTIONS!F16 -> 25 | G13: Always something. New tool, one-off service, surprise fee.
A14: TOTAL FIXED PLATFORM COSTS | B14: =0 -> 0 | C14: =0 -> 0 | D14: =0 -> 0 | E14: =0 -> 0 | F14: =SUM(F5:F13) -> 132 | G14: These run whether you have 1 user or 10,000
A15: Clerk Auth — scales with users (per MAU over 10K) | F15: =IF((ASSUMPTIONS!B5+ASSUMPTIONS!B6+ASSUMPTIONS!B7+ASSUMPTIONS!B8)>10000,((ASSUMPTIONS!B5+ASSUMPTIONS!B6+ASSUMPTIONS!B7+ASSUMPTIONS!B8)-10000)*ASSUMPTIONS!F7,0) -> 0 | G15: Free up to 10K MAU. At launch you're well under — this is $0.
A17: AI COMPUTE COSTS (variable — scales with usage)
A18: Free users — AI cost (amortized from lifetime 50 credits) | F18: =ROUND(ASSUMPTIONS!B5*(ASSUMPTIONS!B21/12)*(ASSUMPTIONS!B20/1000),2) -> 0.04 | G18: 50 lifetime credits amortized over 12 months. Near-zero.
A19: Creator users — monthly AI credit cost | F19: =ROUND(ASSUMPTIONS!B6*ASSUMPTIONS!B22*(ASSUMPTIONS!B20/1000),2) -> 2.25 | G19: 1,500 credits × $0.10/1K = $0.15/user/mo. Very manageable.
A20: Pro users — monthly AI credit cost | F20: =ROUND(ASSUMPTIONS!B7*ASSUMPTIONS!B23*(ASSUMPTIONS!B20/1000),2) -> 4.8 | G20: 6,000 credits × $0.10/1K = $0.60/user/mo.
A21: Installer users — monthly AI credit cost | F21: =ROUND(ASSUMPTIONS!B8*ASSUMPTIONS!B24*(ASSUMPTIONS!B20/1000),2) -> 5 | G21: 25,000 credits × $0.10/1K = $2.50/user/mo.
A22: Top-up delivery AI cost (compute to fulfill top-up purchases) | F22: =ROUND((ASSUMPTIONS!B6*ASSUMPTIONS!B29+ASSUMPTIONS!B7*ASSUMPTIONS!B30+ASSUMPTIONS!B8*ASSUMPTIONS!B31)*ASSUMPTIONS!B33,2) -> 0.74 | G22: Your cost to fulfill top-up orders. ~$0.30 each on avg $22 sale = fat margin.
A23: TOTAL AI COMPUTE COSTS | F23: =SUM(F18:F22) -> 12.83 | G23: Metered credits make this predictable. Top-ups are nearly pure profit.
A25: STORAGE COSTS (Cloudflare R2 — no egress)
A26: Free users — storage cost | F26: =ROUND(ASSUMPTIONS!B5*ASSUMPTIONS!B37*ASSUMPTIONS!B36,4) -> 0.3 | G26: ~200 MB × $0.015/GB = $0.003/user. Basically free.
A27: Creator users — storage cost | F27: =ROUND(ASSUMPTIONS!B6*ASSUMPTIONS!B38*ASSUMPTIONS!B36,4) -> 0.3375 | G27: ~1.5 GB × $0.015 = $0.023/user/mo. Negligible.
A28: Pro users — storage cost | F28: =ROUND(ASSUMPTIONS!B7*ASSUMPTIONS!B39*ASSUMPTIONS!B36,4) -> 0.96 | G28: ~8 GB × $0.015 = $0.12/user/mo.
A29: Installer users — storage cost | F29: =ROUND(ASSUMPTIONS!B8*ASSUMPTIONS!B40*ASSUMPTIONS!B36,4) -> 1.5 | G29: ~50 GB × $0.015 = $0.75/user/mo. Cold archive cuts this ~70% off-season.
A30: TOTAL STORAGE COSTS | F30: =SUM(F26:F29) -> 3.0975 | G30: Storage is NOT your cost problem. AI credits are.
G31: Storage is NOT your cost problem. AI credits are.
A32: MARKETPLACE INFRASTRUCTURE COSTS
A33: Marketplace Stripe processing (on seller payouts) | F33: =ROUND((ROUND(ASSUMPTIONS!B6*ASSUMPTIONS!F22*ASSUMPTIONS!F21*ASSUMPTIONS!F20,2)+ROUND(ASSUMPTIONS!B7*ASSUMPTIONS!F23*ASSUMPTIONS!F21*ASSUMPTIONS!F20,2)+ROUND(ASSUMPTIONS!B8*ASSUMPTIONS!F24*ASSUMPTIONS!F21*ASSUMPTIONS!F20,2))*ASSUMPTIONS!F29,2) -> 4.05 | G33: Stripe charges on every marketplace transaction (already deducted in Revenue sheet)
A34: TOTAL MARKETPLACE COSTS | F34: =F33 -> 4.05
A36: TOTAL OPERATING COSTS / MONTH | F36: =ROUND(F14+F23+F30+F34,2) -> 151.98 | G36: Fixed costs + AI + Storage + Marketplace overhead

Sheet P&L SUMMARY
A1: P&L SUMMARY — CURRENT MONTH SNAPSHOT + ANNUAL VIEW
A2: Snapshot based on current ASSUMPTIONS inputs. Revenue from REVENUE sheet. Costs from COSTS sheet.
A3: LINE ITEM | B3: CURRENT MO | C3: YR 1 (x12) | D3: YR 2 EST | E3: YR 3 EST | G3: NOTES
A4: REVENUE
A5: Subscription MRR | B5: =REVENUE!F9 -> 942.47 | C5: =B5*12 -> 11309.64 | D5: =B5*12*1.5 -> 16964.46 | E5: =B5*12*2.5 -> 28274.1 | G5: Monthly recurring subs — your most predictable revenue
A6: AI Credit Top-Up Sales | B6: =REVENUE!F15 -> 53.9 | C6: =B6*12 -> 646.8 | D6: =B6*12*1.5 -> 970.2 | E6: =B6*12*2.5 -> 1617 | G6: High-margin add-on. Grows as users hit credit caps.
A7: Storage Overage Revenue | B7: =REVENUE!F18 -> 4.5 | C7: =B7*12 -> 54 | D7: =B7*12*1.5 -> 81 | E7: =B7*12*2.5 -> 135 | G7: Small but real. Mostly Installer tier.
A8: Marketplace — Platform Revenue | B8: =REVENUE!F22 -> 45.22 | C8: =B8*12 -> 542.64 | D8: =B8*12*1.5 -> 813.96 | E8: =B8*12*2.5 -> 1356.6 | G8: Your take from marketplace GMV.
A9: Physical & Digital Products (net) | B9: =REVENUE!F27 -> 7.95 | C9: =B9*12 -> 95.4 | D9: =B9*12*1.5 -> 143.1 | E9: =B9*12*2.5 -> 238.5 | G9: Highly seasonal. Mostly Oct-Dec.
A10: GROSS REVENUE | B10: =SUM(B5:B9) -> 1054.04 | C10: =SUM(C5:C9) -> 12648.48 | D10: =SUM(D5:D9) -> 18972.72 | E10: =SUM(E5:E9) -> 31621.2
A11: Less: Stripe Processing | B11: =-REVENUE!F30 -> -38.07 | C11: =B11*12 -> -456.84 | D11: =B11*12*1.5 -> -685.26 | E11: =B11*12*2.5 -> -1142.1
A12: NET REVENUE | B12: =B10+B11 -> 1015.97 | C12: =C10+C11 -> 12191.64 | D12: =D10+D11 -> 18287.46 | E12: =E10+E11 -> 30479.1
A14: COSTS
A15: Fixed Platform Costs | B15: =COSTS!F14 -> 132 | C15: =B15*12 -> 1584 | D15: =B15*12*1.3 -> 2059.2 | E15: =B15*12*1.7 -> 2692.8 | G15: Vercel, Supabase, Resend, Sentry, etc.
A16: Clerk Auth (variable by MAU) | B16: =-COSTS!F15 -> 0 | C16: =B16*12 -> 0 | D16: =B16*12*1.3 -> 0 | E16: =B16*12*1.7 -> 0 | G16: Zero at launch. Kicks in after 10K MAU.
A17: AI Compute Costs | B17: =COSTS!F23 -> 12.83 | C17: =B17*12 -> 153.96 | D17: =B17*12*1.3 -> 200.148 | E17: =B17*12*1.7 -> 261.732 | G17: Your biggest variable cost. Fully metered.
A18: Storage Costs (R2) | B18: =COSTS!F30 -> 3.0975 | C18: =B18*12 -> 37.17 | D18: =B18*12*1.3 -> 48.321 | E18: =B18*12*1.7 -> 63.189 | G18: Tiny. R2's zero-egress policy saves a lot.
A19: Marketplace Infrastructure | B19: =COSTS!F34 -> 4.05 | C19: =B19*12 -> 48.6 | D19: =B19*12*1.3 -> 63.18 | E19: =B19*12*1.7 -> 82.62 | G19: Stripe on marketplace payouts.
A20: TOTAL COSTS | B20: =SUM(B15:B19) -> 151.9775 | C20: =SUM(C15:C19) -> 1823.73 | D20: =SUM(D15:D19) -> 2370.849 | E20: =SUM(E15:E19) -> 3100.341
A22: NET MONTHLY RESULT (+ = profit, - = burn) | B22: =B12-B20 -> 863.9925 | C22: =C12-C20 -> 10367.91 | D22: =D12-D20 -> 15916.611 | E22: =E12-E20 -> 27378.759
A23: Gross Margin % | B23: =IF(B12<>0,B22/B12,0) -> 0.85041143 | C23: =IF(C12<>0,C22/C12,0) -> 0.85041143 | D23: =IF(D12<>0,D22/D12,0) -> 0.87035657 | E23: =IF(E12<>0,E22/E12,0) -> 0.89827977
A25: LAUNCH REALITY CHECK
A26: Total Paying Users (Month 1) | B26: =ASSUMPTIONS!B6+ASSUMPTIONS!B7+ASSUMPTIONS!B8 -> 25 | G26: How many people are actually paying at launch
A27: Monthly Burn Rate (if negative) | B27: =IF(B22<0,ABS(B22),0) -> 0 | G27: How much cash you lose per month at current user counts
A28: Monthly Cash In (if positive) | B28: =IF(B22>0,B22,0) -> 863.9925 | G28: You're profitable if this is positive
A29: Cost per Free User / Mo | B29: =IF(ASSUMPTIONS!B5>0,COSTS!F26/ASSUMPTIONS!B5,0) -> 0.003 | G29: Free users aren't free — they cost ~$0.04/mo each

Sheet SCENARIOS
A1: SCENARIO ANALYSIS — BASE / CONSERVATIVE / WORST CASE
A2: Three revenue scenarios. All costs from COSTS sheet (fixed). Adjust assumption multiples in blue cells below.
A3: METRIC | B3: BASE CASE | C3: CONSERVATIVE | D3: WORST CASE | E3: BEST CASE | G3: NOTES
A4: SCENARIO MULTIPLIERS — adjust these
A5: Creator user count multiplier | B5: 1 | C5: 0.6 | D5: 0.3 | E5: 1.5 | G5: Applied to assumption user counts. 1.0 = use as-is.
A6: Pro user count multiplier | B6: 1 | C6: 0.5 | D6: 0.25 | E6: 2
A7: Installer user count multiplier | B7: 1 | C7: 0.5 | D7: 0.25 | E7: 2
A8: Top-up purchase rate multiplier | B8: 1 | C8: 0.5 | D8: 0.2 | E8: 1.5
A9: Marketplace activity multiplier | B9: 1 | C9: 0.4 | D9: 0.1 | E9: 2 | G9: Marketplace is the most volatile line — seasonal, hard to predict early on
A11: SCENARIO RESULTS
A12: Creator Users | B12: =ROUND(ASSUMPTIONS!B6*B5,0) -> 15 | C12: =ROUND(ASSUMPTIONS!B6*C5,0) -> 9 | D12: =ROUND(ASSUMPTIONS!B6*D5,0) -> 5 | E12: =ROUND(ASSUMPTIONS!B6*E5,0) -> 23
A13: Pro Users | B13: =ROUND(ASSUMPTIONS!B7*B6,0) -> 8 | C13: =ROUND(ASSUMPTIONS!B7*C6,0) -> 4 | D13: =ROUND(ASSUMPTIONS!B7*D6,0) -> 2 | E13: =ROUND(ASSUMPTIONS!B7*E6,0) -> 16
A14: Installer Users | B14: =ROUND(ASSUMPTIONS!B8*B7,0) -> 2 | C14: =ROUND(ASSUMPTIONS!B8*C7,0) -> 1 | D14: =ROUND(ASSUMPTIONS!B8*D7,0) -> 1 | E14: =ROUND(ASSUMPTIONS!B8*E7,0) -> 4
A15: Subscription Revenue / Mo | B15: =ROUND(B12*(1-ASSUMPTIONS!B15)*ASSUMPTIONS!B11+B12*ASSUMPTIONS!B15*ASSUMPTIONS!B11*(1-ASSUMPTIONS!B14)+B13*(1-ASSUMPTIONS!B16)*ASSUMPTIONS!B12+B13*ASSUMPTIONS!B16*ASSUMPTIONS!B12*(1-ASSUMPTIONS!B14)+B14*(1-ASSUMPTIONS!B17)*ASSUMPTIONS!B13+B14*ASSUMPTIONS!B17*ASSUMPTIONS!B13*(1-ASSUMPTIONS!B14),2) -> 942.47 | C15: =ROUND(C12*(1-ASSUMPTIONS!B15)*ASSUMPTIONS!B11+C12*ASSUMPTIONS!B15*ASSUMPTIONS!B11*(1-ASSUMPTIONS!B14)+C13*(1-ASSUMPTIONS!B16)*ASSUMPTIONS!B12+C13*ASSUMPTIONS!B16*ASSUMPTIONS!B12*(1-ASSUMPTIONS!B14)+C14*(1-ASSUMPTIONS!B17)*ASSUMPTIONS!B13+C14*ASSUMPTIONS!B17*ASSUMPTIONS!B13*(1-ASSUMPTIONS!B14),2) -> 499.22 | D15: =ROUND(D12*(1-ASSUMPTIONS!B15)*ASSUMPTIONS!B11+D12*ASSUMPTIONS!B15*ASSUMPTIONS!B11*(1-ASSUMPTIONS!B14)+D13*(1-ASSUMPTIONS!B16)*ASSUMPTIONS!B12+D13*ASSUMPTIONS!B16*ASSUMPTIONS!B12*(1-ASSUMPTIONS!B14)+D14*(1-ASSUMPTIONS!B17)*ASSUMPTIONS!B13+D14*ASSUMPTIONS!B17*ASSUMPTIONS!B13*(1-ASSUMPTIONS!B14),2) -> 329.53 | E15: =ROUND(E12*(1-ASSUMPTIONS!B15)*ASSUMPTIONS!B11+E12*ASSUMPTIONS!B15*ASSUMPTIONS!B11*(1-ASSUMPTIONS!B14)+E13*(1-ASSUMPTIONS!B16)*ASSUMPTIONS!B12+E13*ASSUMPTIONS!B16*ASSUMPTIONS!B12*(1-ASSUMPTIONS!B14)+E14*(1-ASSUMPTIONS!B17)*ASSUMPTIONS!B13+E14*ASSUMPTIONS!B17*ASSUMPTIONS!B13*(1-ASSUMPTIONS!B14),2) -> 1754.32 | G15: Blended monthly + discounted annual
A16: Top-Up Revenue / Mo | B16: =ROUND((B12*ASSUMPTIONS!B29*B8+B13*ASSUMPTIONS!B30*B8+B14*ASSUMPTIONS!B31*B8)*ASSUMPTIONS!B32,2) -> 53.9 | C16: =ROUND((C12*ASSUMPTIONS!B29*C8+C13*ASSUMPTIONS!B30*C8+C14*ASSUMPTIONS!B31*C8)*ASSUMPTIONS!B32,2) -> 14.3 | D16: =ROUND((D12*ASSUMPTIONS!B29*D8+D13*ASSUMPTIONS!B30*D8+D14*ASSUMPTIONS!B31*D8)*ASSUMPTIONS!B32,2) -> 3.52 | E16: =ROUND((E12*ASSUMPTIONS!B29*E8+E13*ASSUMPTIONS!B30*E8+E14*ASSUMPTIONS!B31*E8)*ASSUMPTIONS!B32,2) -> 150.15 | G16: AI credit top-up purchases
A17: Marketplace Revenue / Mo | B17: =ROUND(B12*ASSUMPTIONS!F22*B9*ASSUMPTIONS!F21*ASSUMPTIONS!F20*ASSUMPTIONS!F26+B13*ASSUMPTIONS!F23*B9*ASSUMPTIONS!F21*ASSUMPTIONS!F20*ASSUMPTIONS!F27+B14*ASSUMPTIONS!F24*B9*ASSUMPTIONS!F21*ASSUMPTIONS!F20*ASSUMPTIONS!F28,2) -> 46.58 | C17: =ROUND(C12*ASSUMPTIONS!F22*C9*ASSUMPTIONS!F21*ASSUMPTIONS!F20*ASSUMPTIONS!F26+C13*ASSUMPTIONS!F23*C9*ASSUMPTIONS!F21*ASSUMPTIONS!F20*ASSUMPTIONS!F27+C14*ASSUMPTIONS!F24*C9*ASSUMPTIONS!F21*ASSUMPTIONS!F20*ASSUMPTIONS!F28,2) -> 10.18 | D17: =ROUND(D12*ASSUMPTIONS!F22*D9*ASSUMPTIONS!F21*ASSUMPTIONS!F20*ASSUMPTIONS!F26+D13*ASSUMPTIONS!F23*D9*ASSUMPTIONS!F21*ASSUMPTIONS!F20*ASSUMPTIONS!F27+D14*ASSUMPTIONS!F24*D9*ASSUMPTIONS!F21*ASSUMPTIONS!F20*ASSUMPTIONS!F28,2) -> 1.43 | E17: =ROUND(E12*ASSUMPTIONS!F22*E9*ASSUMPTIONS!F21*ASSUMPTIONS!F20*ASSUMPTIONS!F26+E13*ASSUMPTIONS!F23*E9*ASSUMPTIONS!F21*ASSUMPTIONS!F20*ASSUMPTIONS!F27+E14*ASSUMPTIONS!F24*E9*ASSUMPTIONS!F21*ASSUMPTIONS!F20*ASSUMPTIONS!F28,2) -> 166.14 | G17: Platform take from marketplace GMV
A18: TOTAL REVENUE / MONTH | B18: =B15+B16+B17 -> 1042.95 | C18: =C15+C16+C17 -> 523.7 | D18: =D15+D16+D17 -> 334.48 | E18: =E15+E16+E17 -> 2070.61
A19: Total Costs / Month (from COSTS sheet) | B19: =COSTS!F36 -> 151.98 | C19: =COSTS!F36 -> 151.98 | D19: =COSTS!F36 -> 151.98 | E19: =COSTS!F36 -> 151.98
A20: NET RESULT / MONTH | B20: =B18-B19 -> 890.97 | C20: =C18-C19 -> 371.72 | D20: =D18-D19 -> 182.5 | E20: =E18-E19 -> 1918.63
A21: Annual Revenue Run Rate | B21: =B18*12 -> 12515.4 | C21: =C18*12 -> 6284.4 | D21: =D18*12 -> 4013.76 | E21: =E18*12 -> 24847.32

Sheet PRODUCTS & MERCH
A1: NON-SAAS REVENUE OPPORTUNITIES — PRODUCTS & MERCH
A2: Additional revenue streams beyond subscriptions. Estimates only — validate with audience before investing.
A3: PRODUCT / OPPORTUNITY | B3: PRICE RANGE | C3: COGS EST | D3: GROSS MARGIN | E3: EST UNITS/MO | F3: EST MO REVENUE | G3: NOTES & STRATEGY
A4: YARD SIGNAGE & SHOW BRANDING
A5: Yard Sign — 'Tune to [freq] FM' Digital PDF | B5: $10–$15 | C5: 0.5 | D5: 0.96 | E5: 8 | F5: 96 | G5: Highest-margin product. Hobbyists want these badly. Customize with frequency, show name, year. Instant delivery = zero fulfillment friction.
A6: Yard Sign — Physical Printed (corrugated, weatherproof) | B6: $30–$40 | C6: 14 | D6: 0.6 | E6: 3 | F6: 63 | G6: Via Printful or Gelato print-on-demand. No inventory. Set-and-forget fulfillment.
A7: Show Name + Branding Bundle (sign + social graphic template) | B7: $25–$35 | C7: 1 | D7: 0.96666667 | E7: 2 | F7: 58 | G7: Package: printable sign + Canva social media template + email invite template. High perceived value, near-zero cost.
A8: LED Light-Up Yard Sign (custom order) | B8: $75–$150 | C8: 45 | D8: 0.6 | E8: 1 | F8: 67.5 | G8: Premium. Source via Alibaba or local sign shop. High ticket, lower volume. Best for Installer tier clients.
A9: DIGITAL CONTENT PACKS
A10: Premium Effect Pack (10-15 new effects) | B10: $12–$18 | C10: 0 | D10: 1 | E10: 5 | F10: 75 | G10: Pure digital. Zero COGS. Bundle effects not in base subscription. Create quarterly to keep catalog fresh.
A11: Sequence Pack — Popular Holiday Songs (5-song bundle) | B11: $18–$25 | C11: 0 | D11: 1 | E11: 4 | F11: 86 | G11: Pre-built sequences for recognizable songs (TSO, Mannheim Steamroller, etc.). Creator tier primary buyer.
A12: AI Style Preset Pack (5 curated show styles) | B12: $10–$15 | C12: 0 | D12: 1 | E12: 3 | F12: 37.5 | G12: AI personality presets for different aesthetics: 'Synchronized Intensity', 'Soft Family', 'Club Banger'.
A13: Fixture Layout Template Pack (popular controller configs) | B13: $8–$12 | C13: 0 | D13: 1 | E13: 2 | F13: 20 | G13: Pre-configured layouts for LOR, Falcon, xLights hardware setups. Massive time-saver for new users.
A14: SERVICES & CONSULTATIONS
A15: Show Planning Consultation (1-hr video call) | B15: $79–$119 | C15: 0 | D15: 1 | E15: 1 | F15: 99 | G15: Done-with-you session. Strong upsell for people transitioning from Creator to Pro, or Installer acquiring first big client.
A16: Done-For-You Show Build (full service) | B16: $299–$599 | C16: 50 | D16: 0.88864143 | E16: 0 | F16: 0 | G16: Contractor creates the full sequence for them. Marketplace opportunity: connect buyers with Pro/Installer sellers. Platform takes cut.
A17: HOA / Neighborhood Show Package | B17: $499–$999 | C17: 0 | D17: 1 | E17: 0 | F17: 0 | G17: White-label the platform for HOA-sponsored neighborhood shows. Multi-property + shared FM frequency. Installer-tier target.
A18: HARDWARE-ADJACENT (affiliate / bundled)
A19: Hardware Buying Guide (affiliate links to Amazon/vendors) | B19: Varies | G19: Passive income. Commission on controller, pixel string, power supply purchases. Low effort — write it once.
A20: Controller Programming Service (add-on to Installer tier) | B20: Varies | G20: Installer pays extra to have sequences pre-loaded to SD card and mailed. Operational service revenue.
A21: FM Transmitter Bundle (curated recommendation + affiliate) | B21: Varies | G21: Every light show hobbyist needs one. Curate the best options, affiliate link. Contextual — recommend at export step.
A22: Pixel Mapping Templates for Popular Controllers (LOR, Falcon, xLights) | B22: Varies | G22: Fixture maps for the most common hardware setups. Saves hours. $5-10 each. High volume potential from search traffic.
A24: ESTIMATED MONTHLY PRODUCT REVENUE TOTAL
A25: Conservative total (blue units × avg price) | F25: 0 | G25: Adjust blue 'units/mo' cells above. Revenue is avg_pri
